Workbook

Sheet Painel
D2: XBOX SALES | V2: Samuel B. Lira
D4: Assinaturas, adicionais e desempenho
S6: =HYPERLINK("#'Calculos'!A1","Cálculos") -> Cálculos | W6: =HYPERLINK("#'Base'!A1","Ver base") -> Ver base
B7: Data inicial | G7: Data final | L7: Plano | Q7: Tipo de assinatura | V7: Renovação automática
B8: 45292 | G8: 45657 | L8: Todos | Q8: Todos | V8: Todas
B10: =IF(Calculos!P3=0,"Revise as datas e as opções dos filtros.",IF(Calculos!P6=0,"Nenhuma assinatura encontrada neste recorte.","Dados de 2024. Altere os campos acima para explorar o recorte. Yes = habilitada; No = desabilitada.")) -> Dados de 2024. Altere os campos acima para explorar o recorte. Yes = habilitada; No = desabilitada.
M13: Renovação auto. | U13: Valor dos cupons
D14: Total registrado
L15: =Calculos!P9 -> 0.50169492 | T15: =Calculos!P14 -> 2122
C17: =Calculos!P7 -> 7633
K20: Evolução do valor registrado em 2024
C22: Assinaturas | G22: Ticket médio | U22: Adicionais
C23: =Calculos!P6 -> 295 | G23: =Calculos!P8 -> 25.874576
T25: EA Play
C26: Plano + adicionais − cupons | T26: =Calculos!P12 -> 2940
C29: Planos por valor registrado | T29: Minecraft
T30: =Calculos!P13 -> 3880
T33: =IF(Calculos!P3=0,"n.a.",IF(Calculos!P10=0,"n.a.",TEXT(Calculos!P16,"0.0%")&" do bruto")) -> 69.9% do bruto
K36: Composição antes dos cupons
U39: Uso de cupons
T42: =Calculos!P17 -> 0.82711864
T46: Percentual de assinaturas do recorte com cupom aplicado.
D47: Compare o recorte pelos filtros de período, plano, tipo e renovação.
B53: Base didática DIO. Valores pela data de início, sem projeção de cobrança recorrente. Janeiro, fevereiro e dezembro têm cobertura parcial.

Sheet Calculos
A1: Cálculos e recorte selecionado
A3: =HYPERLINK("#'Painel'!B3","Voltar ao painel") -> Voltar ao painel | O3: Filtros válidos? | P3: =IF(AND(ISNUMBER(Painel!B8),ISNUMBER(Painel!G8),Painel!B8<=Painel!G8,OR(Painel!L8="Todos",Painel!L8="Core",Painel!L8="Standard",Painel!L8="Ultimate"),OR(Painel!Q8="Todos",Painel!Q8="Monthly",Painel!Q8="Quarterly",Painel!Q8="Annual"),OR(Painel!V8="Todas",Painel!V8="Yes",Painel!V8="No")),1,0) -> 1
A4: 1 indica registro incluído. Os valores dos adicionais são brutos; não há rateio de cupons entre produtos.
A6: ID | B6: Início | C6: Plano | D6: Tipo | E6: Renovação | F6: EA normalizado | G6: Bruto | H6: Cupons | I6: Total calculado | J6: Total informado | K6: Incluído? | L6: Diferença | M6: ID repetido? | N6: Divergência? | O6: Assinaturas | P6: =IF($P$3=0,"n.a.",SUM(K7:K1006)) -> 295
A7: =IF(LEN(Base!A7&"")=0,"",Base!A7) -> 3231 | B7: =IF(LEN(A7&"")=0,"",Base!D7) -> 45292 | C7: =IF(LEN(A7&"")=0,"",Base!C7) -> Ultimate | D7: =IF(LEN(A7&"")=0,"",Base!G7) -> Monthly | E7: =IF(LEN(A7&"")=0,"",Base!E7) -> Yes | F7: =IF(LEN(A7&"")=0,"",IF(Base!I7="-",0,Base!I7)) -> 30 | G7: =IF(LEN(A7&"")=0,"",SUM(Base!F7,F7,Base!K7)) -> 65 | H7: =IF(LEN(A7&"")=0,"",Base!L7) -> 5 | I7: =IF(LEN(A7&"")=0,"",G7-H7) -> 60 | J7: =IF(LEN(A7&"")=0,"",Base!M7) -> 60 | K7: =IF(OR(LEN(A7&"")=0,$P$3=0),0,IF(AND(B7>=Painel!$B$8,B7<=Painel!$G$8,OR(Painel!$L$8="Todos",C7=Painel!$L$8),OR(Painel!$Q$8="Todos",D7=Painel!$Q$8),OR(Painel!$V$8="Todas",E7=Painel!$V$8)),1,0)) -> 1 | L7: =IF(LEN(A7&"")=0,"",J7-I7) -> 0 | M7: =IF(LEN(A7&"")=0,0,IF(COUNTIFS(Base!$A$7:$A$1006,A7)>1,1,0)) -> 0 | N7: =IF(LEN(A7&"")=0,0,IF(ABS(L7)>0.005,1,0)) -> 0 | O7: Total registrado | P7: =IF($P$3=0,"n.a.",SUMIFS(J7:J1006,K7:K1006,1)) -> 7633
A8: =IF(LEN(Base!A8&"")=0,"",Base!A8) -> 3232 | B8: =IF(LEN(A8&"")=0,"",Base!D8) -> 45306 | C8: =IF(LEN(A8&"")=0,"",Base!C8) -> Core | D8: =IF(LEN(A8&"")=0,"",Base!G8) -> Annual | E8: =IF(LEN(A8&"")=0,"",Base!E8) -> No | F8: =IF(LEN(A8&"")=0,"",IF(Base!I8="-",0,Base!I8)) -> 0 | G8: =IF(LEN(A8&"")=0,"",SUM(Base!F8,F8,Base!K8)) -> 5 | H8: =IF(LEN(A8&"")=0,"",Base!L8) -> 0 | I8: =IF(LEN(A8&"")=0,"",G8-H8) -> 5 | J8: =IF(LEN(A8&"")=0,"",Base!M8) -> 5 | K8: =IF(OR(LEN(A8&"")=0,$P$3=0),0,IF(AND(B8>=Painel!$B$8,B8<=Painel!$G$8,OR(Painel!$L$8="Todos",C8=Painel!$L$8),OR(Painel!$Q$8="Todos",D8=Painel!$Q$8),OR(Painel!$V$8="Todas",E8=Painel!$V$8)),1,0)) -> 1 | L8: =IF(LEN(A8&"")=0,"",J8-I8) -> 0 | M8: =IF(LEN(A8&"")=0,0,IF(COUNTIFS(Base!$A$7:$A$1006,A8)>1,1,0)) -> 0 | N8: =IF(LEN(A8&"")=0,0,IF(ABS(L8)>0.005,1,0)) -> 0 | O8: Ticket médio | P8: =IF($P$3=0,"n.a.",IF(P6=0,"n.a.",P7/P6)) -> 25.874576
A9: =IF(LEN(Base!A9&"")=0,"",Base!A9) -> 3233 | B9: =IF(LEN(A9&"")=0,"",Base!D9) -> 45332 | C9: =IF(LEN(A9&"")=0,"",Base!C9) -> Standard | D9: =IF(LEN(A9&"")=0,"",Base!G9) -> Quarterly | E9: =IF(LEN(A9&"")=0,"",Base!E9) -> Yes | F9: =IF(LEN(A9&"")=0,"",IF(Base!I9="-",0,Base!I9)) -> 0 | G9: =IF(LEN(A9&"")=0,"",SUM(Base!F9,F9,Base!K9)) -> 30 | H9: =IF(LEN(A9&"")=0,"",Base!L9) -> 10 | I9: =IF(LEN(A9&"")=0,"",G9-H9) -> 20 | J9: =IF(LEN(A9&"")=0,"",Base!M9) -> 20 | K9: =IF(OR(LEN(A9&"")=0,$P$3=0),0,IF(AND(B9>=Painel!$B$8,B9<=Painel!$G$8,OR(Painel!$L$8="Todos",C9=Painel!$L$8),OR(Painel!$Q$8="Todos",D9=Painel!$Q$8),OR(Painel!$V$8="Todas",E9=Painel!$V$8)),1,0)) -> 1 | L9: =IF(LEN(A9&"")=0,"",J9-I9) -> 0 | M9: =IF(LEN(A9&"")=0,0,IF(COUNTIFS(Base!$A$7:$A$1006,A9)>1,1,0)) -> 0 | N9: =IF(LEN(A9&"")=0,0,IF(ABS(L9)>0.005,1,0)) -> 0 | O9: Renovação automática | P9: =IF($P$3=0,"n.a.",IF(P6=0,"n.a.",COUNTIFS(K7:K1006,1,E7:E1006,"Yes")/P6)) -> 0.50169492
A10: =IF(LEN(Base!A10&"")=0,"",Base!A10) -> 3234 | B10: =IF(LEN(A10&"")=0,"",Base!D10) -> 45342 | C10: =IF(LEN(A10&"")=0,"",Base!C10) -> Ultimate | D10: =IF(LEN(A10&"")=0,"",Base!G10) -> Monthly | E10: =IF(LEN(A10&"")=0,"",Base!E10) -> No | F10: =IF(LEN(A10&"")=0,"",IF(Base!I10="-",0,Base!I10)) -> 30 | G10: =IF(LEN(A10&"")=0,"",SUM(Base!F10,F10,Base!K10)) -> 65 | H10: =IF(LEN(A10&"")=0,"",Base!L10) -> 3 | I10: =IF(LEN(A10&"")=0,"",G10-H10) -> 62 | J10: =IF(LEN(A10&"")=0,"",Base!M10) -> 62 | K10: =IF(OR(LEN(A10&"")=0,$P$3=0),0,IF(AND(B10>=Painel!$B$8,B10<=Painel!$G$8,OR(Painel!$L$8="Todos",C10=Painel!$L$8),OR(Painel!$Q$8="Todos",D10=Painel!$Q$8),OR(Painel!$V$8="Todas",E10=Painel!$V$8)),1,0)) -> 1 | L10: =IF(LEN(A10&"")=0,"",J10-I10) -> 0 | M10: =IF(LEN(A10&"")=0,0,IF(COUNTIFS(Base!$A$7:$A$1006,A10)>1,1,0)) -> 0 | N10: =IF(LEN(A10&"")=0,0,IF(ABS(L10)>0.005,1,0)) -> 0 | O10: Bruto | P10: =IF($P$3=0,"n.a.",SUMIFS(G7:G1006,K7:K1006,1)) -> 9755
A11: =IF(LEN(Base!A11&"")=0,"",Base!A11) -> 3235 | B11: =IF(LEN(A11&"")=0,"",Base!D11) -> 45356 | C11: =IF(LEN(A11&"")=0,"",Base!C11) -> Core | D11: =IF(LEN(A11&"")=0,"",Base!G11) -> Monthly | E11: =IF(LEN(A11&"")=0,"",Base!E11) -> Yes | F11: =IF(LEN(A11&"")=0,"",IF(Base!I11="-",0,Base!I11)) -> 0 | G11: =IF(LEN(A11&"")=0,"",SUM(Base!F11,F11,Base!K11)) -> 5 | H11: =IF(LEN(A11&"")=0,"",Base!L11) -> 1 | I11: =IF(LEN(A11&"")=0,"",G11-H11) -> 4 | J11: =IF(LEN(A11&"")=0,"",Base!M11) -> 4 | K11: =IF(OR(LEN(A11&"")=0,$P$3=0),0,IF(AND(B11>=Painel!$B$8,B11<=Painel!$G$8,OR(Painel!$L$8="Todos",C11=Painel!$L$8),OR(Painel!$Q$8="Todos",D11=Painel!$Q$8),OR(Painel!$V$8="Todas",E11=Painel!$V$8)),1,0)) -> 1 | L11: =IF(LEN(A11&"")=0,"",J11-I11) -> 0 | M11: =IF(LEN(A11&"")=0,0,IF(COUNTIFS(Base!$A$7:$A$1006,A11)>1,1,0)) -> 0 | N11: =IF(LEN(A11&"")=0,0,IF(ABS(L11)>0.005,1,0)) -> 0 | O11: Planos | P11: =IF($P$3=0,"n.a.",SUMIFS(Base!F7:F1006,K7:K1006,1)) -> 2935
A12: =IF(LEN(Base!A12&"")=0,"",Base!A12) -> 3236 | B12: =IF(LEN(A12&"")=0,"",Base!D12) -> 45353 | C12: =IF(LEN(A12&"")=0,"",Base!C12) -> Standard | D12: =IF(LEN(A12&"")=0,"",Base!G12) -> Monthly | E12: =IF(LEN(A12&"")=0,"",Base!E12) -> No | F12: =IF(LEN(A12&"")=0,"",IF(Base!I12="-",0,Base!I12)) -> 0 | G12: =IF(LEN(A12&"")=0,"",SUM(Base!F12,F12,Base!K12)) -> 30 | H12: =IF(LEN(A12&"")=0,"",Base!L12) -> 2 | I12: =IF(LEN(A12&"")=0,"",G12-H12) -> 28 | J12: =IF(LEN(A12&"")=0,"",Base!M12) -> 28 | K12: =IF(OR(LEN(A12&"")=0,$P$3=0),0,IF(AND(B12>=Painel!$B$8,B12<=Painel!$G$8,OR(Painel!$L$8="Todos",C12=Painel!$L$8),OR(Painel!$Q$8="Todos",D12=Painel!$Q$8),OR(Painel!$V$8="Todas",E12=Painel!$V$8)),1,0)) -> 1 | L12: =IF(LEN(A12&"")=0,"",J12-I12) -> 0 | M12: =IF(LEN(A12&"")=0,0,IF(COUNTIFS(Base!$A$7:$A$1006,A12)>1,1,0)) -> 0 | N12: =IF(LEN(A12&"")=0,0,IF(ABS(L12)>0.005,1,0)) -> 0 | O12: EA Play | P12: =IF($P$3=0,"n.a.",SUMIFS(F7:F1006,K7:K1006,1)) -> 2940
A13: =IF(LEN(Base!A13&"")=0,"",Base!A13) -> 3237 | B13: =IF(LEN(A13&"")=0,"",Base!D13) -> 45354 | C13: =IF(LEN(A13&"")=0,"",Base!C13) -> Ultimate | D13: =IF(LEN(A13&"")=0,"",Base!G13) -> Quarterly | E13: =IF(LEN(A13&"")=0,"",Base!E13) -> Yes | F13: =IF(LEN(A13&"")=0,"",IF(Base!I13="-",0,Base!I13)) -> 30 | G13: =IF(LEN(A13&"")=0,"",SUM(Base!F13,F13,Base!K13)) -> 65 | H13: =IF(LEN(A13&"")=0,"",Base!L13) -> 10 | I13: =IF(LEN(A13&"")=0,"",G13-H13) -> 55 | J13: =IF(LEN(A13&"")=0,"",Base!M13) -> 55 | K13: =IF(OR(LEN(A13&"")=0,$P$3=0),0,IF(AND(B13>=Painel!$B$8,B13<=Painel!$G$8,OR(Painel!$L$8="Todos",C13=Painel!$L$8),OR(Painel!$Q$8="Todos",D13=Painel!$Q$8),OR(Painel!$V$8="Todas",E13=Painel!$V$8)),1,0)) -> 1 | L13: =IF(LEN(A13&"")=0,"",J13-I13) -> 0 | M13: =IF(LEN(A13&"")=0,0,IF(COUNTIFS(Base!$A$7:$A$1006,A13)>1,1,0)) -> 0 | N13: =IF(LEN(A13&"")=0,0,IF(ABS(L13)>0.005,1,0)) -> 0 | O13: Minecraft | P13: =IF($P$3=0,"n.a.",SUMIFS(Base!K7:K1006,K7:K1006,1)) -> 3880
A14: =IF(LEN(Base!A14&"")=0,"",Base!A14) -> 3238 | B14: =IF(LEN(A14&"")=0,"",Base!D14) -> 45355 | C14: =IF(LEN(A14&"")=0,"",Base!C14) -> Core | D14: =IF(LEN(A14&"")=0,"",Base!G14) -> Annual | E14: =IF(LEN(A14&"")=0,"",Base!E14) -> Yes | F14: =IF(LEN(A14&"")=0,"",IF(Base!I14="-",0,Base!I14)) -> 0 | G14: =IF(LEN(A14&"")=0,"",SUM(Base!F14,F14,Base!K14)) -> 5 | H14: =IF(LEN(A14&"")=0,"",Base!L14) -> 0 | I14: =IF(LEN(A14&"")=0,"",G14-H14) -> 5 | J14: =IF(LEN(A14&"")=0,"",Base!M14) -> 5 | K14: =IF(OR(LEN(A14&"")=0,$P$3=0),0,IF(AND(B14>=Painel!$B$8,B14<=Painel!$G$8,OR(Painel!$L$8="Todos",C14=Painel!$L$8),OR(Painel!$Q$8="Todos",D14=Painel!$Q$8),OR(Painel!$V$8="Todas",E14=Painel!$V$8)),1,0)) -> 1 | L14: =IF(LEN(A14&"")=0,"",J14-I14) -> 0 | M14: =IF(LEN(A14&"")=0,0,IF(COUNTIFS(Base!$A$7:$A$1006,A14)>1,1,0)) -> 0 | N14: =IF(LEN(A14&"")=0,0,IF(ABS(L14)>0.005,1,0)) -> 0 | O14: Cupons | P14: =IF($P$3=0,"n.a.",SUMIFS(H7:H1006,K7:K1006,1)) -> 2122
A15: =IF(LEN(Base!A15&"")=0,"",Base!A15) -> 3239 | B15: =IF(LEN(A15&"")=0,"",Base!D15) -> 45356 | C15: =IF(LEN(A15&"")=0,"",Base!C15) -> Ultimate | D15: =IF(LEN(A15&"")=0,"",Base!G15) -> Monthly | E15: =IF(LEN(A15&"")=0,"",Base!E15) -> No | F15: =IF(LEN(A15&"")=0,"",IF(Base!I15="-",0,Base!I15)) -> 30 | G15: =IF(LEN(A15&"")=0,"",SUM(Base!F15,F15,Base!K15)) -> 65 | H15: =IF(LEN(A15&"")=0,"",Base!L15) -> 5 | I15: =IF(LEN(A15&"")=0,"",G15-H15) -> 60 | J15: =IF(LEN(A15&"")=0,"",Base!M15) -> 60 | K15: =IF(OR(LEN(A15&"")=0,$P$3=0),0,IF(AND(B15>=Painel!$B$8,B15<=Painel!$G$8,OR(Painel!$L$8="Todos",C15=Painel!$L$8),OR(Painel!$Q$8="Todos",D15=Painel!$Q$8),OR(Painel!$V$8="Todas",E15=Painel!$V$8)),1,0)) -> 1 | L15: =IF(LEN(A15&"")=0,"",J15-I15) -> 0 | M15: =IF(LEN(A15&"")=0,0,IF(COUNTIFS(Base!$A$7:$A$1006,A15)>1,1,0)) -> 0 | N15: =IF(LEN(A15&"")=0,0,IF(ABS(L15)>0.005,1,0)) -> 0 | O15: Adicionais | P15: =IF($P$3=0,"n.a.",SUM(P12:P13)) -> 6820
A16: =IF(LEN(Base!A16&"")=0,"",Base!A16) -> 3240 | B16: =IF(LEN(A16&"")=0,"",Base!D16) -> 45357 | C16: =IF(LEN(A16&"")=0,"",Base!C16) -> Standard | D16: =IF(LEN(A16&"")=0,"",Base!G16) -> Quarterly | E16: =IF(LEN(A16&"")=0,"",Base!E16) -> Yes | F16: =IF(LEN(A16&"")=0,"",IF(Base!I16="-",0,Base!I16)) -> 0 | G16: =IF(LEN(A16&"")=0,"",SUM(Base!F16,F16,Base!K16)) -> 30 | H16: =IF(LEN(A16&"")=0,"",Base!L16) -> 15 | I16: =IF(LEN(A16&"")=0,"",G16-H16) -> 15 | J16: =IF(LEN(A16&"")=0,"",Base!M16) -> 15 | K16: =IF(OR(LEN(A16&"")=0,$P$3=0),0,IF(AND(B16>=Painel!$B$8,B16<=Painel!$G$8,OR(Painel!$L$8="Todos",C16=Painel!$L$8),OR(Painel!$Q$8="Todos",D16=Painel!$Q$8),OR(Painel!$V$8="Todas",E16=Painel!$V$8)),1,0)) -> 1 | L16: =IF(LEN(A16&"")=0,"",J16-I16) -> 0 | M16: =IF(LEN(A16&"")=0,0,IF(COUNTIFS(Base!$A$7:$A$1006,A16)>1,1,0)) -> 0 | N16: =IF(LEN(A16&"")=0,0,IF(ABS(L16)>0.005,1,0)) -> 0 | O16: Participação adicionais | P16: =IF($P$3=0,"n.a.",IF(P10=0,"n.a.",P15/P10)) -> 0.69912865
A17: =IF(LEN(Base!A17&"")=0,"",Base!A17) -> 3241 | B17: =IF(LEN(A17&"")=0,"",Base!D17) -> 45358 | C17: =IF(LEN(A17&"")=0,"",Base!C17) -> Core | D17: =IF(LEN(A17&"")=0,"",Base!G17) -> Monthly | E17: =IF(LEN(A17&"")=0,"",Base!E17) -> No | F17: =IF(LEN(A17&"")=0,"",IF(Base!I17="-",0,Base!I17)) -> 0 | G17: =IF(LEN(A17&"")=0,"",SUM(Base!F17,F17,Base!K17)) -> 5 | H17: =IF(LEN(A17&"")=0,"",Base!L17) -> 1 | I17: =IF(LEN(A17&"")=0,"",G17-H17) -> 4 | J17: =IF(LEN(A17&"")=0,"",Base!M17) -> 4 | K17: =IF(OR(LEN(A17&"")=0,$P$3=0),0,IF(AND(B17>=Painel!$B$8,B17<=Painel!$G$8,OR(Painel!$L$8="Todos",C17=Painel!$L$8),OR(Painel!$Q$8="Todos",D17=Painel!$Q$8),OR(Painel!$V$8="Todas",E17=Painel!$V$8)),1,0)) -> 1 | L17: =IF(LEN(A17&"")=0,"",J17-I17) -> 0 | M17: =IF(LEN(A17&"")=0,0,IF(COUNTIFS(Base!$A$7:$A$1006,A17)>1,1,0)) -> 0 | N17: =IF(LEN(A17&"")=0,0,IF(ABS(L17)>0.005,1,0)) -> 0 | O17: Incidência cupons | P17: =IF($P$3=0,"n.a.",IF(P6=0,"n.a.",COUNTIFS(K7:K1006,1,H7:H1006,">0")/P6)) -> 0.82711864
A18: =IF(LEN(Base!A18&"")=0,"",Base!A18) -> 3242 | B18: =IF(LEN(A18&"")=0,"",Base!D18) -> 45359 | C18: =IF(LEN(A18&"")=0,"",Base!C18) -> Ultimate | D18: =IF(LEN(A18&"")=0,"",Base!G18) -> Annual | E18: =IF(LEN(A18&"")=0,"",Base!E18) -> Yes | F18: =IF(LEN(A18&"")=0,"",IF(Base!I18="-",0,Base!I18)) -> 30 | G18: =IF(LEN(A18&"")=0,"",SUM(Base!F18,F18,Base!K18)) -> 65 | H18: =IF(LEN(A18&"")=0,"",Base!L18) -> 20 | I18: =IF(LEN(A18&"")=0,"",G18-H18) -> 45 | J18: =IF(LEN(A18&"")=0,"",Base!M18) -> 45 | K18: =IF(OR(LEN(A18&"")=0,$P$3=0),0,IF(AND(B18>=Painel!$B$8,B18<=Painel!$G$8,OR(Painel!$L$8="Todos",C18=Painel!$L$8),OR(Painel!$Q$8="Todos",D18=Painel!$Q$8),OR(Painel!$V$8="Todas",E18=Painel!$V$8)),1,0)) -> 1 | L18: =IF(LEN(A18&"")=0,"",J18-I18) -> 0 | M18: =IF(LEN(A18&"")=0,0,IF(COUNTIFS(Base!$A$7:$A$1006,A18)>1,1,0)) -> 0 | N18: =IF(LEN(A18&"")=0,0,IF(ABS(L18)>0.005,1,0)) -> 0
A19: =IF(LEN(Base!A19&"")=0,"",Base!A19) -> 3243 | B19: =IF(LEN(A19&"")=0,"",Base!D19) -> 45360 | C19: =IF(LEN(A19&"")=0,"",Base!C19) -> Standard | D19: =IF(LEN(A19&"")=0,"",Base!G19) -> Monthly | E19: =IF(LEN(A19&"")=0,"",Base!E19) -> No | F19: =IF(LEN(A19&"")=0,"",IF(Base!I19="-",0,Base!I19)) -> 0 | G19: =IF(LEN(A19&"")=0,"",SUM(Base!F19,F19,Base!K19)) -> 30 | H19: =IF(LEN(A19&"")=0,"",Base!L19) -> 10 | I19: =IF(LEN(A19&"")=0,"",G19-H19) -> 20 | J19: =IF(LEN(A19&"")=0,"",Base!M19) -> 20 | K19: =IF(OR(LEN(A19&"")=0,$P$3=0),0,IF(AND(B19>=Painel!$B$8,B19<=Painel!$G$8,OR(Painel!$L$8="Todos",C19=Painel!$L$8),OR(Painel!$Q$8="Todos",D19=Painel!$Q$8),OR(Painel!$V$8="Todas",E19=Painel!$V$8)),1,0)) -> 1 | L19: =IF(LEN(A19&"")=0,"",J19-I19) -> 0 | M19: =IF(LEN(A19&"")=0,0,IF(COUNTIFS(Base!$A$7:$A$1006,A19)>1,1,0)) -> 0 | N19: =IF(LEN(A19&"")=0,0,IF(ABS(L19)>0.005,1,0)) -> 0
A20: =IF(LEN(Base!A20&"")=0,"",Base!A20) -> 3244 | B20: =IF(LEN(A20&"")=0,"",Base!D20) -> 45361 | C20: =IF(LEN(A20&"")=0,"",Base!C20) -> Core | D20: =IF(LEN(A20&"")=0,"",Base!G20) -> Quarterly | E20: =IF(LEN(A20&"")=0,"",Base!E20) -> Yes | F20: =IF(LEN(A20&"")=0,"",IF(Base!I20="-",0,Base!I20)) -> 0 | G20: =IF(LEN(A20&"")=0,"",SUM(Base!F20,F20,Base!K20)) -> 5 | H20: =IF(LEN(A20&"")=0,"",Base!L20) -> 0 | I20: =IF(LEN(A20&"")=0,"",G20-H20) -> 5 | J20: =IF(LEN(A20&"")=0,"",Base!M20) -> 5 | K20: =IF(OR(LEN(A20&"")=0,$P$3=0),0,IF(AND(B20>=Painel!$B$8,B20<=Painel!$G$8,OR(Painel!$L$8="Todos",C20=Painel!$L$8),OR(Painel!$Q$8="Todos",D20=Painel!$Q$8),OR(Painel!$V$8="Todas",E20=Painel!$V$8)),1,0)) -> 1 | L20: =IF(LEN(A20&"")=0,"",J20-I20) -> 0 | M20: =IF(LEN(A20&"")=0,0,IF(COUNTIFS(Base!$A$7:$A$1006,A20)>1,1,0)) -> 0 | N20: =IF(LEN(A20&"")=0,0,IF(ABS(L20)>0.005,1,0)) -> 0
A21: =IF(LEN(Base!A21&"")=0,"",Base!A21) -> 3245 | B21: =IF(LEN(A21&"")=0,"",Base!D21) -> 45362 | C21: =IF(LEN(A21&"")=0,"",Base!C21) -> Ultimate | D21: =IF(LEN(A21&"")=0,"",Base!G21) -> Monthly | E21: =IF(LEN(A21&"")=0,"",Base!E21) -> No | F21: =IF(LEN(A21&"")=0,"",IF(Base!I21="-",0,Base!I21)) -> 30 | G21: =IF(LEN(A21&"")=0,"",SUM(Base!F21,F21,Base!K21)) -> 65 | H21: =IF(LEN(A21&"")=0,"",Base!L21) -> 8 | I21: =IF(LEN(A21&"")=0,"",G21-H21) -> 57 | J21: =IF(LEN(A21&"")=0,"",Base!M21) -> 57 | K21: =IF(OR(LEN(A21&"")=0,$P$3=0),0,IF(AND(B21>=Painel!$B$8,B21<=Painel!$G$8,OR(Painel!$L$8="Todos",C21=Painel!$L$8),OR(Painel!$Q$8="Todos",D21=Painel!$Q$8),OR(Painel!$V$8="Todas",E21=Painel!$V$8)),1,0)) -> 1 | L21: =IF(LEN(A21&"")=0,"",J21-I21) -> 0 | M21: =IF(LEN(A21&"")=0,0,IF(COUNTIFS(Base!$A$7:$A$1006,A21)>1,1,0)) -> 0 | N21: =IF(LEN(A21&"")=0,0,IF(ABS(L21)>0.005,1,0)) -> 0 | O21: Mês | P21: Valor registrado | Q21: Assinaturas | T21: Plano | U21: Valor registrado | V21: Ordem | X21: Plano | Y21: Valor registrado
A22: =IF(LEN(Base!A22&"")=0,"",Base!A22) -> 3246 | B22: =IF(LEN(A22&"")=0,"",Base!D22) -> 45363 | C22: =IF(LEN(A22&"")=0,"",Base!C22) -> Standard | D22: =IF(LEN(A22&"")=0,"",Base!G22) -> Annual | E22: =IF(LEN(A22&"")=0,"",Base!E22) -> Yes | F22: =IF(LEN(A22&"")=0,"",IF(Base!I22="-",0,Base!I22)) -> 0 | G22: =IF(LEN(A22&"")=0,"",SUM(Base!F22,F22,Base!K22)) -> 30 | H22: =IF(LEN(A22&"")=0,"",Base!L22) -> 12 | I22: =IF(LEN(A22&"")=0,"",G22-H22) -> 18 | J22: =IF(LEN(A22&"")=0,"",Base!M22) -> 18 | K22: =IF(OR(LEN(A22&"")=0,$P$3=0),0,IF(AND(B22>=Painel!$B$8,B22<=Painel!$G$8,OR(Painel!$L$8="Todos",C22=Painel!$L$8),OR(Painel!$Q$8="Todos",D22=Painel!$Q$8),OR(Painel!$V$8="Todas",E22=Painel!$V$8)),1,0)) -> 1 | L22: =IF(LEN(A22&"")=0,"",J22-I22) -> 0 | M22: =IF(LEN(A22&"")=0,0,IF(COUNTIFS(Base!$A$7:$A$1006,A22)>1,1,0)) -> 0 | N22: =IF(LEN(A22&"")=0,0,IF(ABS(L22)>0.005,1,0)) -> 0 | O22: jan | P22: =IF($P$3=0,NA(),SUMIFS($J$7:$J$1006,$K$7:$K$1006,1,$B$7:$B$1006,">="&R22,$B$7:$B$1006,"<"&DATE(YEAR(R22),MONTH(R22)+1,1))) -> 65 | Q22: =COUNTIFS($K$7:$K$1006,1,$B$7:$B$1006,">="&R22,$B$7:$B$1006,"<"&DATE(YEAR(R22),MONTH(R22)+1,1)) -> 2 | R22: 45292 | T22: Core | U22: =SUMIFS($J$7:$J$1006,$K$7:$K$1006,1,$C$7:$C$1006,T22) -> 444 | V22: =COUNTIFS($U$22:$U$24,">"&U22)+COUNTIFS($U$22:U22,U22) -> 3 | X22: =INDEX($T$22:$T$24,MATCH(1,$V$22:$V$24,0)) -> Ultimate | Y22: =IF($P$3=0,NA(),INDEX($U$22:$U$24,MATCH(1,$V$22:$V$24,0))) -> 5388
A23: =IF(LEN(Base!A23&"")=0,"",Base!A23) -> 3247 | B23: =IF(LEN(A23&"")=0,"",Base!D23) -> 45364 | C23: =IF(LEN(A23&"")=0,"",Base!C23) -> Core | D23: =IF(LEN(A23&"")=0,"",Base!G23) -> Monthly | E23: =IF(LEN(A23&"")=0,"",Base!E23) -> No | F23: =IF(LEN(A23&"")=0,"",IF(Base!I23="-",0,Base!I23)) -> 0 | G23: =IF(LEN(A23&"")=0,"",SUM(Base!F23,F23,Base!K23)) -> 5 | H23: =IF(LEN(A23&"")=0,"",Base!L23) -> 2 | I23: =IF(LEN(A23&"")=0,"",G23-H23) -> 3 | J23: =IF(LEN(A23&"")=0,"",Base!M23) -> 3 | K23: =IF(OR(LEN(A23&"")=0,$P$3=0),0,IF(AND(B23>=Painel!$B$8,B23<=Painel!$G$8,OR(Painel!$L$8="Todos",C23=Painel!$L$8),OR(Painel!$Q$8="Todos",D23=Painel!$Q$8),OR(Painel!$V$8="Todas",E23=Painel!$V$8)),1,0)) -> 1 | L23: =IF(LEN(A23&"")=0,"",J23-I23) -> 0 | M23: =IF(LEN(A23&"")=0,0,IF(COUNTIFS(Base!$A$7:$A$1006,A23)>1,1,0)) -> 0 | N23: =IF(LEN(A23&"")=0,0,IF(ABS(L23)>0.005,1,0)) -> 0 | O23: fev | P23: =IF($P$3=0,NA(),SUMIFS($J$7:$J$1006,$K$7:$K$1006,1,$B$7:$B$1006,">="&R23,$B$7:$B$1006,"<"&DATE(YEAR(R23),MONTH(R23)+1,1))) -> 82 | Q23: =COUNTIFS($K$7:$K$1006,1,$B$7:$B$1006,">="&R23,$B$7:$B$1006,"<"&DATE(YEAR(R23),MONTH(R23)+1,1)) -> 2 | R23: 45323 | T23: Standard | U23: =SUMIFS($J$7:$J$1006,$K$7:$K$1006,1,$C$7:$C$1006,T23) -> 1801 | V23: =COUNTIFS($U$22:$U$24,">"&U23)+COUNTIFS($U$22:U23,U23) -> 2 | X23: =INDEX($T$22:$T$24,MATCH(2,$V$22:$V$24,0)) -> Standard | Y23: =IF($P$3=0,NA(),INDEX($U$22:$U$24,MATCH(2,$V$22:$V$24,0))) -> 1801
A24: =IF(LEN(Base!A24&"")=0,"",Base!A24) -> 3248 | B24: =IF(LEN(A24&"")=0,"",Base!D24) -> 45365 | C24: =IF(LEN(A24&"")=0,"",Base!C24) -> Ultimate | D24: =IF(LEN(A24&"")=0,"",Base!G24) -> Quarterly | E24: =IF(LEN(A24&"")=0,"",Base!E24) -> Yes | F24: =IF(LEN(A24&"")=0,"",IF(Base!I24="-",0,Base!I24)) -> 30 | G24: =IF(LEN(A24&"")=0,"",SUM(Base!F24,F24,Base!K24)) -> 65 | H24: =IF(LEN(A24&"")=0,"",Base!L24) -> 7 | I24: =IF(LEN(A24&"")=0,"",G24-H24) -> 58 | J24: =IF(LEN(A24&"")=0,"",Base!M24) -> 58 | K24: =IF(OR(LEN(A24&"")=0,$P$3=0),0,IF(AND(B24>=Painel!$B$8,B24<=Painel!$G$8,OR(Painel!$L$8="Todos",C24=Painel!$L$8),OR(Painel!$Q$8="Todos",D24=Painel!$Q$8),OR(Painel!$V$8="Todas",E24=Painel!$V$8)),1,0)) -> 1 | L24: =IF(LEN(A24&"")=0,"",J24-I24) -> 0 | M24: =IF(LEN(A24&"")=0,0,IF(COUNTIFS(Base!$A$7:$A$1006,A24)>1,1,0)) -> 0 | N24: =IF(LEN(A24&"")=0,0,IF(ABS(L24)>0.005,1,0)) -> 0 | O24: mar | P24: =IF($P$3=0,NA(),SUMIFS($J$7:$J$1006,$K$7:$K$1006,1,$B$7:$B$1006,">="&R24,$B$7:$B$1006,"<"&DATE(YEAR(R24),MONTH(R24)+1,1))) -> 801 | Q24: =COUNTIFS($K$7:$K$1006,1,$B$7:$B$1006,">="&R24,$B$7:$B$1006,"<"&DATE(YEAR(R24),MONTH(R24)+1,1)) -> 31 | R24: 45352 | T24: Ultimate | U24: =SUMIFS($J$7:$J$1006,$K$7:$K$1006,1,$C$7:$C$1006,T24) -> 5388 | V24: =COUNTIFS($U$22:$U$24,">"&U24)+COUNTIFS($U$22:U24,U24) -> 1 | X24: =INDEX($T$22:$T$24,MATCH(3,$V$22:$V$24,0)) -> Core | Y24: =IF($P$3=0,NA(),INDEX($U$22:$U$24,MATCH(3,$V$22:$V$24,0))) -> 444
A25: =IF(LEN(Base!A25&"")=0,"",Base!A25) -> 3249 | B25: =IF(LEN(A25&"")=0,"",Base!D25) -> 45366 | C25: =IF(LEN(A25&"")=0,"",Base!C25) -> Standard | D25: =IF(LEN(A25&"")=0,"",Base!G25) -> Monthly | E25: =IF(LEN(A25&"")=0,"",Base!E25) -> No | F25: =IF(LEN(A25&"")=0,"",IF(Base!I25="-",0,Base!I25)) -> 0 | G25: =IF(LEN(A25&"")=0,"",SUM(Base!F25,F25,Base!K25)) -> 30 | H25: =IF(LEN(A25&"")=0,"",Base!L25) -> 5 | I25: =IF(LEN(A25&"")=0,"",G25-H25) -> 25 | J25: =IF(LEN(A25&"")=0,"",Base!M25) -> 25 | K25: =IF(OR(LEN(A25&"")=0,$P$3=0),0,IF(AND(B25>=Painel!$B$8,B25<=Painel!$G$8,OR(Painel!$L$8="Todos",C25=Painel!$L$8),OR(Painel!$Q$8="Todos",D25=Painel!$Q$8),OR(Painel!$V$8="Todas",E25=Painel!$V$8)),1,0)) -> 1 | L25: =IF(LEN(A25&"")=0,"",J25-I25) -> 0 | M25: =IF(LEN(A25&"")=0,0,IF(COUNTIFS(Base!$A$7:$A$1006,A25)>1,1,0)) -> 0 | N25: =IF(LEN(A25&"")=0,0,IF(ABS(L25)>0.005,1,0)) -> 0 | O25: abr | P25: =IF($P$3=0,NA(),SUMIFS($J$7:$J$1006,$K$7:$K$1006,1,$B$7:$B$1006,">="&R25,$B$7:$B$1006,"<"&DATE(YEAR(R25),MONTH(R25)+1,1))) -> 782 | Q25: =COUNTIFS($K$7:$K$1006,1,$B$7:$B$1006,">="&R25,$B$7:$B$1006,"<"&DATE(YEAR(R25),MONTH(R25)+1,1)) -> 30 | R25: 45383
A26: =IF(LEN(Base!A26&"")=0,"",Base!A26) -> 3250 | B26: =IF(LEN(A26&"")=0,"",Base!D26) -> 45367 | C26: =IF(LEN(A26&"")=0,"",Base!C26) -> Core | D26: =IF(LEN(A26&"")=0,"",Base!G26) -> Annual | E26: =IF(LEN(A26&"")=0,"",Base!E26) -> Yes | F26: =IF(LEN(A26&"")=0,"",IF(Base!I26="-",0,Base!I26)) -> 0 | G26: =IF(LEN(A26&"")=0,"",SUM(Base!F26,F26,Base!K26)) -> 5 | H26: =IF(LEN(A26&"")=0,"",Base!L26) -> 0 | I26: =IF(LEN(A26&"")=0,"",G26-H26) -> 5 | J26: =IF(LEN(A26&"")=0,"",Base!M26) -> 5 | K26: =IF(OR(LEN(A26&"")=0,$P$3=0),0,IF(AND(B26>=Painel!$B$8,B26<=Painel!$G$8,OR(Painel!$L$8="Todos",C26=Painel!$L$8),OR(Painel!$Q$8="Todos",D26=Painel!$Q$8),OR(Painel!$V$8="Todas",E26=Painel!$V$8)),1,0)) -> 1 | L26: =IF(LEN(A26&"")=0,"",J26-I26) -> 0 | M26: =IF(LEN(A26&"")=0,0,IF(COUNTIFS(Base!$A$7:$A$1006,A26)>1,1,0)) -> 0 | N26: =IF(LEN(A26&"")=0,0,IF(ABS(L26)>0.005,1,0)) -> 0 | O26: mai | P26: =IF($P$3=0,NA(),SUMIFS($J$7:$J$1006,$K$7:$K$1006,1,$B$7:$B$1006,">="&R26,$B$7:$B$1006,"<"&DATE(YEAR(R26),MONTH(R26)+1,1))) -> 777 | Q26: =COUNTIFS($K$7:$K$1006,1,$B$7:$B$1006,">="&R26,$B$7:$B$1006,"<"&DATE(YEAR(R26),MONTH(R26)+1,1)) -> 31 | R26: 45413
A27: =IF(LEN(Base!A27&"")=0,"",Base!A27) -> 3251 | B27: =IF(LEN(A27&"")=0,"",Base!D27) -> 45368 | C27: =IF(LEN(A27&"")=0,"",Base!C27) -> Ultimate | D27: =IF(LEN(A27&"")=0,"",Base!G27) -> Monthly | E27: =IF(LEN(A27&"")=0,"",Base!E27) -> No | F27: =IF(LEN(A27&"")=0,"",IF(Base!I27="-",0,Base!I27)) -> 30 | G27: =IF(LEN(A27&"")=0,"",SUM(Base!F27,F27,Base!K27)) -> 65 | H27: =IF(LEN(A27&"")=0,"",Base!L27) -> 3 | I27: =IF(LEN(A27&"")=0,"",G27-H27) -> 62 | J27: =IF(LEN(A27&"")=0,"",Base!M27) -> 62 | K27: =IF(OR(LEN(A27&"")=0,$P$3=0),0,IF(AND(B27>=Painel!$B$8,B27<=Painel!$G$8,OR(Painel!$L$8="Todos",C27=Painel!$L$8),OR(Painel!$Q$8="Todos",D27=Painel!$Q$8),OR(Painel!$V$8="Todas",E27=Painel!$V$8)),1,0)) -> 1 | L27: =IF(LEN(A27&"")=0,"",J27-I27) -> 0 | M27: =IF(LEN(A27&"")=0,0,IF(COUNTIFS(Base!$A$7:$A$1006,A27)>1,1,0)) -> 0 | N27: =IF(LEN(A27&"")=0,0,IF(ABS(L27)>0.005,1,0)) -> 0 | O27: jun | P27: =IF($P$3=0,NA(),SUMIFS($J$7:$J$1006,$K$7:$K$1006,1,$B$7:$B$1006,">="&R27,$B$7:$B$1006,"<"&DATE(YEAR(R27),MONTH(R27)+1,1))) -> 770 | Q27: =COUNTIFS($K$7:$K$1006,1,$B$7:$B$1006,">="&R27,$B$7:$B$1006,"<"&DATE(YEAR(R27),MONTH(R27)+1,1)) -> 30 | R27: 45444
A28: =IF(LEN(Base!A28&"")=0,"",Base!A28) -> 3252 | B28: =IF(LEN(A28&"")=0,"",Base!D28) -> 45369 | C28: =IF(LEN(A28&"")=0,"",Base!C28) -> Standard | D28: =IF(LEN(A28&"")=0,"",Base!G28) -> Quarterly | E28: =IF(LEN(A28&"")=0,"",Base!E28) -> Yes | F28: =IF(LEN(A28&"")=0,"",IF(Base!I28="-",0,Base!I28)) -> 0 | G28: =IF(LEN(A28&"")=0,"",SUM(Base!F28,F28,Base!K28)) -> 30 | H28: =IF(LEN(A28&"")=0,"",Base!L28) -> 15 | I28: =IF(LEN(A28&"")=0,"",G28-H28) -> 15 | J28: =IF(LEN(A28&"")=0,"",Base!M28) -> 15 | K28: =IF(OR(LEN(A28&"")=0,$P$3=0),0,IF(AND(B28>=Painel!$B$8,B28<=Painel!$G$8,OR(Painel!$L$8="Todos",C28=Painel!$L$8),OR(Painel!$Q$8="Todos",D28=Painel!$Q$8),OR(Painel!$V$8="Todas",E28=Painel!$V$8)),1,0)) -> 1 | L28: =IF(LEN(A28&"")=0,"",J28-I28) -> 0 | M28: =IF(LEN(A28&"")=0,0,IF(COUNTIFS(Base!$A$7:$A$1006,A28)>1,1,0)) -> 0 | N28: =IF(LEN(A28&"")=0,0,IF(ABS(L28)>0.005,1,0)) -> 0 | O28: jul | P28: =IF($P$3=0,NA(),SUMIFS($J$7:$J$1006,$K$7:$K$1006,1,$B$7:$B$1006,">="&R28,$B$7:$B$1006,"<"&DATE(YEAR(R28),MONTH(R28)+1,1))) -> 784 | Q28: =COUNTIFS($K$7:$K$1006,1,$B$7:$B$1006,">="&R28,$B$7:$B$1006,"<"&DATE(YEAR(R28),MONTH(R28)+1,1)) -> 31 | R28: 45474 | T28: Componente | U28: Bruto
A29: =IF(LEN(Base!A29&"")=0,"",Base!A29) -> 3253 | B29: =IF(LEN(A29&"")=0,"",Base!D29) -> 45370 | C29: =IF(LEN(A29&"")=0,"",Base!C29) -> Core | D29: =IF(LEN(A29&"")=0,"",Base!G29) -> Monthly | E29: =IF(LEN(A29&"")=0,"",Base!E29) -> No | F29: =IF(LEN(A29&"")=0,"",IF(Base!I29="-",0,Base!I29)) -> 0 | G29: =IF(LEN(A29&"")=0,"",SUM(Base!F29,F29,Base!K29)) -> 5 | H29: =IF(LEN(A29&"")=0,"",Base!L29) -> 1 | I29: =IF(LEN(A29&"")=0,"",G29-H29) -> 4 | J29: =IF(LEN(A29&"")=0,"",Base!M29) -> 4 | K29: =IF(OR(LEN(A29&"")=0,$P$3=0),0,IF(AND(B29>=Painel!$B$8,B29<=Painel!$G$8,OR(Painel!$L$8="Todos",C29=Painel!$L$8),OR(Painel!$Q$8="Todos",D29=Painel!$Q$8),OR(Painel!$V$8="Todas",E29=Painel!$V$8)),1,0)) -> 1 | L29: =IF(LEN(A29&"")=0,"",J29-I29) -> 0 | M29: =IF(LEN(A29&"")=0,0,IF(COUNTIFS(Base!$A$7:$A$1006,A29)>1,1,0)) -> 0 | N29: =IF(LEN(A29&"")=0,0,IF(ABS(L29)>0.005,1,0)) -> 0 | O29: ago | P29: =IF($P$3=0,NA(),SUMIFS($J$7:$J$1006,$K$7:$K$1006,1,$B$7:$B$1006,">="&R29,$B$7:$B$1006,"<"&DATE(YEAR(R29),MONTH(R29)+1,1))) -> 787 | Q29: =COUNTIFS($K$7:$K$1006,1,$B$7:$B$1006,">="&R29,$B$7:$B$1006,"<"&DATE(YEAR(R29),MONTH(R29)+1,1)) -> 31 | R29: 45505 | T29: Planos | U29: =IF($P$3=0,NA(),P11) -> 2935
A30: =IF(LEN(Base!A30&"")=0,"",Base!A30) -> 3254 | B30: =IF(LEN(A30&"")=0,"",Base!D30) -> 45371 | C30: =IF(LEN(A30&"")=0,"",Base!C30) -> Ultimate | D30: =IF(LEN(A30&"")=0,"",Base!G30) -> Annual | E30: =IF(LEN(A30&"")=0,"",Base!E30) -> Yes | F30: =IF(LEN(A30&"")=0,"",IF(Base!I30="-",0,Base!I30)) -> 30 | G30: =IF(LEN(A30&"")=0,"",SUM(Base!F30,F30,Base!K30)) -> 65 | H30: =IF(LEN(A30&"")=0,"",Base!L30) -> 20 | I30: =IF(LEN(A30&"")=0,"",G30-H30) -> 45 | J30: =IF(LEN(A30&"")=0,"",Base!M30) -> 45 | K30: =IF(OR(LEN(A30&"")=0,$P$3=0),0,IF(AND(B30>=Painel!$B$8,B30<=Painel!$G$8,OR(Painel!$L$8="Todos",C30=Painel!$L$8),OR(Painel!$Q$8="Todos",D30=Painel!$Q$8),OR(Painel!$V$8="Todas",E30=Painel!$V$8)),1,0)) -> 1 | L30: =IF(LEN(A30&"")=0,"",J30-I30) -> 0 | M30: =IF(LEN(A30&"")=0,0,IF(COUNTIFS(Base!$A$7:$A$1006,A30)>1,1,0)) -> 0 | N30: =IF(LEN(A30&"")=0,0,IF(ABS(L30)>0.005,1,0)) -> 0 | O30: set | P30: =IF($P$3=0,NA(),SUMIFS($J$7:$J$1006,$K$7:$K$1006,1,$B$7:$B$1006,">="&R30,$B$7:$B$1006,"<"&DATE(YEAR(R30),MONTH(R30)+1,1))) -> 780 | Q30: =COUNTIFS($K$7:$K$1006,1,$B$7:$B$1006,">="&R30,$B$7:$B$1006,"<"&DATE(YEAR(R30),MONTH(R30)+1,1)) -> 30 | R30: 45536 | T30: EA Play | U30: =IF($P$3=0,NA(),P12) -> 2940
A31: =IF(LEN(Base!A31&"")=0,"",Base!A31) -> 3255 | B31: =IF(LEN(A31&"")=0,"",Base!D31) -> 45372 | C31: =IF(LEN(A31&"")=0,"",Base!C31) -> Standard | D31: =IF(LEN(A31&"")=0,"",Base!G31) -> Monthly | E31: =IF(LEN(A31&"")=0,"",Base!E31) -> No | F31: =IF(LEN(A31&"")=0,"",IF(Base!I31="-",0,Base!I31)) -> 0 | G31: =IF(LEN(A31&"")=0,"",SUM(Base!F31,F31,Base!K31)) -> 30 | H31: =IF(LEN(A31&"")=0,"",Base!L31) -> 10 | I31: =IF(LEN(A31&"")=0,"",G31-H31) -> 20 | J31: =IF(LEN(A31&"")=0,"",Base!M31) -> 20 | K31: =IF(OR(LEN(A31&"")=0,$P$3=0),0,IF(AND(B31>=Painel!$B$8,B31<=Painel!$G$8,OR(Painel!$L$8="Todos",C31=Painel!$L$8),OR(Painel!$Q$8="Todos",D31=Painel!$Q$8),OR(Painel!$V$8="Todas",E31=Painel!$V$8)),1,0)) -> 1 | L31: =IF(LEN(A31&"")=0,"",J31-I31) -> 0 | M31: =IF(LEN(A31&"")=0,0,IF(COUNTIFS(Base!$A$7:$A$1006,A31)>1,1,0)) -> 0 | N31: =IF(LEN(A31&"")=0,0,IF(ABS(L31)>0.005,1,0)) -> 0 | O31: out | P31: =IF($P$3=0,NA(),SUMIFS($J$7:$J$1006,$K$7:$K$1006,1,$B$7:$B$1006,">="&R31,$B$7:$B$1006,"<"&DATE(YEAR(R31),MONTH(R31)+1,1))) -> 832 | Q31: =COUNTIFS($K$7:$K$1006,1,$B$7:$B$1006,">="&R31,$B$7:$B$1006,"<"&DATE(YEAR(R31),MONTH(R31)+1,1)) -> 31 | R31: 45566 | T31: Minecraft | U31: =IF($P$3=0,NA(),P13) -> 3880
A32: =IF(LEN(Base!A32&"")=0,"",Base!A32) -> 3256 | B32: =IF(LEN(A32&"")=0,"",Base!D32) -> 45373 | C32: =IF(LEN(A32&"")=0,"",Base!C32) -> Core | D32: =IF(LEN(A32&"")=0,"",Base!G32) -> Quarterly | E32: =IF(LEN(A32&"")=0,"",Base!E32) -> Yes | F32: =IF(LEN(A32&"")=0,"",IF(Base!I32="-",0,Base!I32)) -> 0 | G32: =IF(LEN(A32&"")=0,"",SUM(Base!F32,F32,Base!K32)) -> 5 | H32: =IF(LEN(A32&"")=0,"",Base!L32) -> 0 | I32: =IF(LEN(A32&"")=0,"",G32-H32) -> 5 | J32: =IF(LEN(A32&"")=0,"",Base!M32) -> 5 | K32: =IF(OR(LEN(A32&"")=0,$P$3=0),0,IF(AND(B32>=Painel!$B$8,B32<=Painel!$G$8,OR(Painel!$L$8="Todos",C32=Painel!$L$8),OR(Painel!$Q$8="Todos",D32=Painel!$Q$8),OR(Painel!$V$8="Todas",E32=Painel!$V$8)),1,0)) -> 1 | L32: =IF(LEN(A32&"")=0,"",J32-I32) -> 0 | M32: =IF(LEN(A32&"")=0,0,IF(COUNTIFS(Base!$A$7:$A$1006,A32)>1,1,0)) -> 0 | N32: =IF(LEN(A32&"")=0,0,IF(ABS(L32)>0.005,1,0)) -> 0 | O32: nov | P32: =IF($P$3=0,NA(),SUMIFS($J$7:$J$1006,$K$7:$K$1006,1,$B$7:$B$1006,">="&R32,$B$7:$B$1006,"<"&DATE(YEAR(R32),MONTH(R32)+1,1))) -> 784 | Q32: =COUNTIFS($K$7:$K$1006,1,$B$7:$B$1006,">="&R32,$B$7:$B$1006,"<"&DATE(YEAR(R32),MONTH(R32)+1,1)) -> 30 | R32: 45597
A33: =IF(LEN(Base!A33&"")=0,"",Base!A33) -> 3257 | B33: =IF(LEN(A33&"")=0,"",Base!D33) -> 45374 | C33: =IF(LEN(A33&"")=0,"",Base!C33) -> Ultimate | D33: =IF(LEN(A33&"")=0,"",Base!G33) -> Monthly | E33: =IF(LEN(A33&"")=0,"",Base!E33) -> No | F33: =IF(LEN(A33&"")=0,"",IF(Base!I33="-",0,Base!I33)) -> 30 | G33: =IF(LEN(A33&"")=0,"",SUM(Base!F33,F33,Base!K33)) -> 65 | H33: =IF(LEN(A33&"")=0,"",Base!L33) -> 5 | I33: =IF(LEN(A33&"")=0,"",G33-H33) -> 60 | J33: =IF(LEN(A33&"")=0,"",Base!M33) -> 60 | K33: =IF(OR(LEN(A33&"")=0,$P$3=0),0,IF(AND(B33>=Painel!$B$8,B33<=Painel!$G$8,OR(Painel!$L$8="Todos",C33=Painel!$L$8),OR(Painel!$Q$8="Todos",D33=Painel!$Q$8),OR(Painel!$V$8="Todas",E33=Painel!$V$8)),1,0)) -> 1 | L33: =IF(LEN(A33&"")=0,"",J33-I33) -> 0 | M33: =IF(LEN(A33&"")=0,0,IF(COUNTIFS(Base!$A$7:$A$1006,A33)>1,1,0)) -> 0 | N33: =IF(LEN(A33&"")=0,0,IF(ABS(L33)>0.005,1,0)) -> 0 | O33: dez | P33: =IF($P$3=0,NA(),SUMIFS($J$7:$J$1006,$K$7:$K$1006,1,$B$7:$B$1006,">="&R33,$B$7:$B$1006,"<"&DATE(YEAR(R33),MONTH(R33)+1,1))) -> 389 | Q33: =COUNTIFS($K$7:$K$1006,1,$B$7:$B$1006,">="&R33,$B$7:$B$1006,"<"&DATE(YEAR(R33),MONTH(R33)+1,1)) -> 16 | R33: 45627
A34: =IF(LEN(Base!A34&"")=0,"",Base!A34) -> 3258 | B34: =IF(LEN(A34&"")=0,"",Base!D34) -> 45375 | C34: =IF(LEN(A34&"")=0,"",Base!C34) -> Standard | D34: =IF(LEN(A34&"")=0,"",Base!G34) -> Annual | E34: =IF(LEN(A34&"")=0,"",Base!E34) -> Yes | F34: =IF(LEN(A34&"")=0,"",IF(Base!I34="-",0,Base!I34)) -> 0 | G34: =IF(LEN(A34&"")=0,"",SUM(Base!F34,F34,Base!K34)) -> 30 | H34: =IF(LEN(A34&"")=0,"",Base!L34) -> 15 | I34: =IF(LEN(A34&"")=0,"",G34-H34) -> 15 | J34: =IF(LEN(A34&"")=0,"",Base!M34) -> 15 | K34: =IF(OR(LEN(A34&"")=0,$P$3=0),0,IF(AND(B34>=Painel!$B$8,B34<=Painel!$G$8,OR(Painel!$L$8="Todos",C34=Painel!$L$8),OR(Painel!$Q$8="Todos",D34=Painel!$Q$8),OR(Painel!$V$8="Todas",E34=Painel!$V$8)),1,0)) -> 1 | L34: =IF(LEN(A34&"")=0,"",J34-I34) -> 0 | M34: =IF(LEN(A34&"")=0,0,IF(COUNTIFS(Base!$A$7:$A$1006,A34)>1,1,0)) -> 0 | N34: =IF(LEN(A34&"")=0,0,IF(ABS(L34)>0.005,1,0)) -> 0
A35: =IF(LEN(Base!A35&"")=0,"",Base!A35) -> 3259 | B35: =IF(LEN(A35&"")=0,"",Base!D35) -> 45376 | C35: =IF(LEN(A35&"")=0,"",Base!C35) -> Core | D35: =IF(LEN(A35&"")=0,"",Base!G35) -> Monthly | E35: =IF(LEN(A35&"")=0,"",Base!E35) -> No | F35: =IF(LEN(A35&"")=0,"",IF(Base!I35="-",0,Base!I35)) -> 0 | G35: =IF(LEN(A35&"")=0,"",SUM(Base!F35,F35,Base!K35)) -> 5 | H35: =IF(LEN(A35&"")=0,"",Base!L35) -> 1 | I35: =IF(LEN(A35&"")=0,"",G35-H35) -> 4 | J35: =IF(LEN(A35&"")=0,"",Base!M35) -> 4 | K35: =IF(OR(LEN(A35&"")=0,$P$3=0),0,IF(AND(B35>=Painel!$B$8,B35<=Painel!$G$8,OR(Painel!$L$8="Todos",C35=Painel!$L$8),OR(Painel!$Q$8="Todos",D35=Painel!$Q$8),OR(Painel!$V$8="Todas",E35=Painel!$V$8)),1,0)) -> 1 | L35: =IF(LEN(A35&"")=0,"",J35-I35) -> 0 | M35: =IF(LEN(A35&"")=0,0,IF(COUNTIFS(Base!$A$7:$A$1006,A35)>1,1,0)) -> 0 | N35: =IF(LEN(A35&"")=0,0,IF(ABS(L35)>0.005,1,0)) -> 0
A36: =IF(LEN(Base!A36&"")=0,"",Base!A36) -> 3260 | B36: =IF(LEN(A36&"")=0,"",Base!D36) -> 45377 | C36: =IF(LEN(A36&"")=0,"",Base!C36) -> Ultimate | D36: =IF(LEN(A36&"")=0,"",Base!G36) -> Quarterly | E36: =IF(LEN(A36&"")=0,"",Base!E36) -> Yes | F36: =IF(LEN(A36&"")=0,"",IF(Base!I36="-",0,Base!I36)) -> 30 | G36: =IF(LEN(A36&"")=0,"",SUM(Base!F36,F36,Base!K36)) -> 65 | H36: =IF(LEN(A36&"")=0,"",Base!L36) -> 7 | I36: =IF(LEN(A36&"")=0,"",G36-H36) -> 58 | J36: =IF(LEN(A36&"")=0,"",Base!M36) -> 58 | K36: =IF(OR(LEN(A36&"")=0,$P$3=0),0,IF(AND(B36>=Painel!$B$8,B36<=Painel!$G$8,OR(Painel!$L$8="Todos",C36=Painel!$L$8),OR(Painel!$Q$8="Todos",D36=Painel!$Q$8),OR(Painel!$V$8="Todas",E36=Painel!$V$8)),1,0)) -> 1 | L36: =IF(LEN(A36&"")=0,"",J36-I36) -> 0 | M36: =IF(LEN(A36&"")=0,0,IF(COUNTIFS(Base!$A$7:$A$1006,A36)>1,1,0)) -> 0 | N36: =IF(LEN(A36&"")=0,0,IF(ABS(L36)>0.005,1,0)) -> 0
A37: =IF(LEN(Base!A37&"")=0,"",Base!A37) -> 3261 | B37: =IF(LEN(A37&"")=0,"",Base!D37) -> 45378 | C37: =IF(LEN(A37&"")=0,"",Base!C37) -> Standard | D37: =IF(LEN(A37&"")=0,"",Base!G37) -> Monthly | E37: =IF(LEN(A37&"")=0,"",Base!E37) -> No | F37: =IF(LEN(A37&"")=0,"",IF(Base!I37="-",0,Base!I37)) -> 0 | G37: =IF(LEN(A37&"")=0,"",SUM(Base!F37,F37,Base!K37)) -> 30 | H37: =IF(LEN(A37&"")=0,"",Base!L37) -> 10 | I37: =IF(LEN(A37&"")=0,"",G37-H37) -> 20 | J37: =IF(LEN(A37&"")=0,"",Base!M37) -> 20 | K37: =IF(OR(LEN(A37&"")=0,$P$3=0),0,IF(AND(B37>=Painel!$B$8,B37<=Painel!$G$8,OR(Painel!$L$8="Todos",C37=Painel!$L$8),OR(Painel!$Q$8="Todos",D37=Painel!$Q$8),OR(Painel!$V$8="Todas",E37=Painel!$V$8)),1,0)) -> 1 | L37: =IF(LEN(A37&"")=0,"",J37-I37) -> 0 | M37: =IF(LEN(A37&"")=0,0,IF(COUNTIFS(Base!$A$7:$A$1006,A37)>1,1,0)) -> 0 | N37: =IF(LEN(A37&"")=0,0,IF(ABS(L37)>0.005,1,0)) -> 0
A38: =IF(LEN(Base!A38&"")=0,"",Base!A38) -> 3262 | B38: =IF(LEN(A38&"")=0,"",Base!D38) -> 45379 | C38: =IF(LEN(A38&"")=0,"",Base!C38) -> Core | D38: =IF(LEN(A38&"")=0,"",Base!G38) -> Annual | E38: =IF(LEN(A38&"")=0,"",Base!E38) -> Yes | F38: =IF(LEN(A38&"")=0,"",IF(Base!I38="-",0,Base!I38)) -> 0 | G38: =IF(LEN(A38&"")=0,"",SUM(Base!F38,F38,Base!K38)) -> 5 | H38: =IF(LEN(A38&"")=0,"",Base!L38) -> 0 | I38: =IF(LEN(A38&"")=0,"",G38-H38) -> 5 | J38: =IF(LEN(A38&"")=0,"",Base!M38) -> 5 | K38: =IF(OR(LEN(A38&"")=0,$P$3=0),0,IF(AND(B38>=Painel!$B$8,B38<=Painel!$G$8,OR(Painel!$L$8="Todos",C38=Painel!$L$8),OR(Painel!$Q$8="Todos",D38=Painel!$Q$8),OR(Painel!$V$8="Todas",E38=Painel!$V$8)),1,0)) -> 1 | L38: =IF(LEN(A38&"")=0,"",J38-I38) -> 0 | M38: =IF(LEN(A38&"")=0,0,IF(COUNTIFS(Base!$A$7:$A$1006,A38)>1,1,0)) -> 0 | N38: =IF(LEN(A38&"")=0,0,IF(ABS(L38)>0.005,1,0)) -> 0 | O38: Conciliação da base | P38: Obtido | Q38: Esperado
A39: =IF(LEN(Base!A39&"")=0,"",Base!A39) -> 3263 | B39: =IF(LEN(A39&"")=0,"",Base!D39) -> 45380 | C39: =IF(LEN(A39&"")=0,"",Base!C39) -> Ultimate | D39: =IF(LEN(A39&"")=0,"",Base!G39) -> Monthly | E39: =IF(LEN(A39&"")=0,"",Base!E39) -> No | F39: =IF(LEN(A39&"")=0,"",IF(Base!I39="-",0,Base!I39)) -> 30 | G39: =IF(LEN(A39&"")=0,"",SUM(Base!F39,F39,Base!K39)) -> 65 | H39: =IF(LEN(A39&"")=0,"",Base!L39) -> 3 | I39: =IF(LEN(A39&"")=0,"",G39-H39) -> 62 | J39: =IF(LEN(A39&"")=0,"",Base!M39) -> 62 | K39: =IF(OR(LEN(A39&"")=0,$P$3=0),0,IF(AND(B39>=Painel!$B$8,B39<=Painel!$G$8,OR(Painel!$L$8="Todos",C39=Painel!$L$8),OR(Painel!$Q$8="Todos",D39=Painel!$Q$8),OR(Painel!$V$8="Todas",E39=Painel!$V$8)),1,0)) -> 1 | L39: =IF(LEN(A39&"")=0,"",J39-I39) -> 0 | M39: =IF(LEN(A39&"")=0,0,IF(COUNTIFS(Base!$A$7:$A$1006,A39)>1,1,0)) -> 0 | N39: =IF(LEN(A39&"")=0,0,IF(ABS(L39)>0.005,1,0)) -> 0 | O39: IDs preenchidos | P39: =COUNTA(Base!A7:A1006) -> 295 | Q39: 295
A40: =IF(LEN(Base!A40&"")=0,"",Base!A40) -> 3264 | B40: =IF(LEN(A40&"")=0,"",Base!D40) -> 45381 | C40: =IF(LEN(A40&"")=0,"",Base!C40) -> Standard | D40: =IF(LEN(A40&"")=0,"",Base!G40) -> Quarterly | E40: =IF(LEN(A40&"")=0,"",Base!E40) -> Yes | F40: =IF(LEN(A40&"")=0,"",IF(Base!I40="-",0,Base!I40)) -> 0 | G40: =IF(LEN(A40&"")=0,"",SUM(Base!F40,F40,Base!K40)) -> 30 | H40: =IF(LEN(A40&"")=0,"",Base!L40) -> 15 | I40: =IF(LEN(A40&"")=0,"",G40-H40) -> 15 | J40: =IF(LEN(A40&"")=0,"",Base!M40) -> 15 | K40: =IF(OR(LEN(A40&"")=0,$P$3=0),0,IF(AND(B40>=Painel!$B$8,B40<=Painel!$G$8,OR(Painel!$L$8="Todos",C40=Painel!$L$8),OR(Painel!$Q$8="Todos",D40=Painel!$Q$8),OR(Painel!$V$8="Todas",E40=Painel!$V$8)),1,0)) -> 1 | L40: =IF(LEN(A40&"")=0,"",J40-I40) -> 0 | M40: =IF(LEN(A40&"")=0,0,IF(COUNTIFS(Base!$A$7:$A$1006,A40)>1,1,0)) -> 0 | N40: =IF(LEN(A40&"")=0,0,IF(ABS(L40)>0.005,1,0)) -> 0 | O40: Total informado | P40: =SUM(Base!M7:M1006) -> 7633 | Q40: 7633
A41: =IF(LEN(Base!A41&"")=0,"",Base!A41) -> 3265 | B41: =IF(LEN(A41&"")=0,"",Base!D41) -> 45382 | C41: =IF(LEN(A41&"")=0,"",Base!C41) -> Core | D41: =IF(LEN(A41&"")=0,"",Base!G41) -> Monthly | E41: =IF(LEN(A41&"")=0,"",Base!E41) -> No | F41: =IF(LEN(A41&"")=0,"",IF(Base!I41="-",0,Base!I41)) -> 0 | G41: =IF(LEN(A41&"")=0,"",SUM(Base!F41,F41,Base!K41)) -> 5 | H41: =IF(LEN(A41&"")=0,"",Base!L41) -> 1 | I41: =IF(LEN(A41&"")=0,"",G41-H41) -> 4 | J41: =IF(LEN(A41&"")=0,"",Base!M41) -> 4 | K41: =IF(OR(LEN(A41&"")=0,$P$3=0),0,IF(AND(B41>=Painel!$B$8,B41<=Painel!$G$8,OR(Painel!$L$8="Todos",C41=Painel!$L$8),OR(Painel!$Q$8="Todos",D41=Painel!$Q$8),OR(Painel!$V$8="Todas",E41=Painel!$V$8)),1,0)) -> 1 | L41: =IF(LEN(A41&"")=0,"",J41-I41) -> 0 | M41: =IF(LEN(A41&"")=0,0,IF(COUNTIFS(Base!$A$7:$A$1006,A41)>1,1,0)) -> 0 | N41: =IF(LEN(A41&"")=0,0,IF(ABS(L41)>0.005,1,0)) -> 0 | O41: Bruto menos cupons | P41: =SUM(I7:I1006) -> 7633 | Q41: 7633
A42: =IF(LEN(Base!A42&"")=0,"",Base!A42) -> 3266 | B42: =IF(LEN(A42&"")=0,"",Base!D42) -> 45383 | C42: =IF(LEN(A42&"")=0,"",Base!C42) -> Core | D42: =IF(LEN(A42&"")=0,"",Base!G42) -> Monthly | E42: =IF(LEN(A42&"")=0,"",Base!E42) -> Yes | F42: =IF(LEN(A42&"")=0,"",IF(Base!I42="-",0,Base!I42)) -> 0 | G42: =IF(LEN(A42&"")=0,"",SUM(Base!F42,F42,Base!K42)) -> 5 | H42: =IF(LEN(A42&"")=0,"",Base!L42) -> 0 | I42: =IF(LEN(A42&"")=0,"",G42-H42) -> 5 | J42: =IF(LEN(A42&"")=0,"",Base!M42) -> 5 | K42: =IF(OR(LEN(A42&"")=0,$P$3=0),0,IF(AND(B42>=Painel!$B$8,B42<=Painel!$G$8,OR(Painel!$L$8="Todos",C42=Painel!$L$8),OR(Painel!$Q$8="Todos",D42=Painel!$Q$8),OR(Painel!$V$8="Todas",E42=Painel!$V$8)),1,0)) -> 1 | L42: =IF(LEN(A42&"")=0,"",J42-I42) -> 0 | M42: =IF(LEN(A42&"")=0,0,IF(COUNTIFS(Base!$A$7:$A$1006,A42)>1,1,0)) -> 0 | N42: =IF(LEN(A42&"")=0,0,IF(ABS(L42)>0.005,1,0)) -> 0 | O42: Diferença de totais | P42: =P40-P41 -> 0 | Q42: 0
...

Sheet Base
A1: Base de assinaturas
A3: Fonte DIO: https://hermes.dio.me/files/assets/805d54f9-6d53-4246-bed7-4aa2da615923.xlsx
A4: 295 registros fornecidos. Cálculos preparados até a linha 1006 (1.000 registros). Preserve os nomes e a ordem dos campos.
A5: =HYPERLINK("#'Painel'!B3","Voltar ao painel") -> Voltar ao painel
A6: Subscriber ID | B6: Name | C6: Plan | D6: Start Date | E6: Auto Renewal | F6: Subscription Price | G6: Subscription Type | H6: EA Play Season Pass | I6: EA Play Season Pass Price | J6: Minecraft Season Pass | K6: Minecraft Season Pass Price | L6: Coupon Value | M6: Total Value
A7: 3231 | B7: João Silva | C7: Ultimate | D7: 45292 | E7: Yes | F7: 15 | G7: Monthly | H7: Yes | I7: 30 | J7: Yes | K7: 20 | L7: 5 | M7: 60
A8: 3232 | B8: Maria Oliveira | C8: Core | D8: 45306 | E8: No | F8: 5 | G8: Annual | H8: No | I8: - | J8: No | K8: 0 | L8: 0 | M8: 5
A9: 3233 | B9: Lucas Fernandes | C9: Standard | D9: 45332 | E9: Yes | F9: 10 | G9: Quarterly | H9: No | I9: - | J9: Yes | K9: 20 | L9: 10 | M9: 20
A10: 3234 | B10: Ana Souza | C10: Ultimate | D10: 45342 | E10: No | F10: 15 | G10: Monthly | H10: Yes | I10: 30 | J10: Yes | K10: 20 | L10: 3 | M10: 62
A11: 3235 | B11: Pedro Gonçalves | C11: Core | D11: 45356 | E11: Yes | F11: 5 | G11: Monthly | H11: No | I11: - | J11: No | K11: 0 | L11: 1 | M11: 4
A12: 3236 | B12: Felipe Costa | C12: Standard | D12: 45353 | E12: No | F12: 10 | G12: Monthly | H12: No | I12: - | J12: Yes | K12: 20 | L12: 2 | M12: 28
A13: 3237 | B13: Camila Ribeiro | C13: Ultimate | D13: 45354 | E13: Yes | F13: 15 | G13: Quarterly | H13: Yes | I13: 30 | J13: Yes | K13: 20 | L13: 10 | M13: 55
A14: 3238 | B14: André Mendes | C14: Core | D14: 45355 | E14: Yes | F14: 5 | G14: Annual | H14: No | I14: - | J14: No | K14: 0 | L14: 0 | M14: 5
A15: 3239 | B15: Sofia Almeida | C15: Ultimate | D15: 45356 | E15: No | F15: 15 | G15: Monthly | H15: Yes | I15: 30 | J15: Yes | K15: 20 | L15: 5 | M15: 60
A16: 3240 | B16: Bruno Martins | C16: Standard | D16: 45357 | E16: Yes | F16: 10 | G16: Quarterly | H16: No | I16: - | J16: Yes | K16: 20 | L16: 15 | M16: 15
A17: 3241 | B17: Rita Castro | C17: Core | D17: 45358 | E17: No | F17: 5 | G17: Monthly | H17: No | I17: - | J17: No | K17: 0 | L17: 1 | M17: 4
A18: 3242 | B18: Marco Túlio | C18: Ultimate | D18: 45359 | E18: Yes | F18: 15 | G18: Annual | H18: Yes | I18: 30 | J18: Yes | K18: 20 | L18: 20 | M18: 45
A19: 3243 | B19: Lívia Silveira | C19: Standard | D19: 45360 | E19: No | F19: 10 | G19: Monthly | H19: No | I19: - | J19: Yes | K19: 20 | L19: 10 | M19: 20
A20: 3244 | B20: Diogo Sousa | C20: Core | D20: 45361 | E20: Yes | F20: 5 | G20: Quarterly | H20: No | I20: - | J20: No | K20: 0 | L20: 0 | M20: 5
A21: 3245 | B21: Fernanda Lima | C21: Ultimate | D21: 45362 | E21: No | F21: 15 | G21: Monthly | H21: Yes | I21: 30 | J21: Yes | K21: 20 | L21: 8 | M21: 57
A22: 3246 | B22: Caio Pereira | C22: Standard | D22: 45363 | E22: Yes | F22: 10 | G22: Annual | H22: No | I22: - | J22: Yes | K22: 20 | L22: 12 | M22: 18
A23: 3247 | B23: Beatriz Gomes | C23: Core | D23: 45364 | E23: No | F23: 5 | G23: Monthly | H23: No | I23: - | J23: No | K23: 0 | L23: 2 | M23: 3
A24: 3248 | B24: Cesar Oliveira | C24: Ultimate | D24: 45365 | E24: Yes | F24: 15 | G24: Quarterly | H24: Yes | I24: 30 | J24: Yes | K24: 20 | L24: 7 | M24: 58
A25: 3249 | B25: Débora Machado | C25: Standard | D25: 45366 | E25: No | F25: 10 | G25: Monthly | H25: No | I25: - | J25: Yes | K25: 20 | L25: 5 | M25: 25
A26: 3250 | B26: Eduardo Vargas | C26: Core | D26: 45367 | E26: Yes | F26: 5 | G26: Annual | H26: No | I26: - | J26: No | K26: 0 | L26: 0 | M26: 5
A27: 3251 | B27: Gabriela Santos | C27: Ultimate | D27: 45368 | E27: No | F27: 15 | G27: Monthly | H27: Yes | I27: 30 | J27: Yes | K27: 20 | L27: 3 | M27: 62
A28: 3252 | B28: Henrique Dias | C28: Standard | D28: 45369 | E28: Yes | F28: 10 | G28: Quarterly | H28: No | I28: - | J28: Yes | K28: 20 | L28: 15 | M28: 15
A29: 3253 | B29: Isabela Moreira | C29: Core | D29: 45370 | E29: No | F29: 5 | G29: Monthly | H29: No | I29: - | J29: No | K29: 0 | L29: 1 | M29: 4
A30: 3254 | B30: Joaquim Barbosa | C30: Ultimate | D30: 45371 | E30: Yes | F30: 15 | G30: Annual | H30: Yes | I30: 30 | J30: Yes | K30: 20 | L30: 20 | M30: 45
A31: 3255 | B31: Lara Rocha | C31: Standard | D31: 45372 | E31: No | F31: 10 | G31: Monthly | H31: No | I31: - | J31: Yes | K31: 20 | L31: 10 | M31: 20
A32: 3256 | B32: Matheus Silva | C32: Core | D32: 45373 | E32: Yes | F32: 5 | G32: Quarterly | H32: No | I32: - | J32: No | K32: 0 | L32: 0 | M32: 5
A33: 3257 | B33: Nicole Costa | C33: Ultimate | D33: 45374 | E33: No | F33: 15 | G33: Monthly | H33: Yes | I33: 30 | J33: Yes | K33: 20 | L33: 5 | M33: 60
A34: 3258 | B34: Otávio Mendonça | C34: Standard | D34: 45375 | E34: Yes | F34: 10 | G34: Annual | H34: No | I34: - | J34: Yes | K34: 20 | L34: 15 | M34: 15
A35: 3259 | B35: Paula Ferreira | C35: Core | D35: 45376 | E35: No | F35: 5 | G35: Monthly | H35: No | I35: - | J35: No | K35: 0 | L35: 1 | M35: 4
A36: 3260 | B36: Raquel Alves | C36: Ultimate | D36: 45377 | E36: Yes | F36: 15 | G36: Quarterly | H36: Yes | I36: 30 | J36: Yes | K36: 20 | L36: 7 | M36: 58
A37: 3261 | B37: Samuel Pires | C37: Standard | D37: 45378 | E37: No | F37: 10 | G37: Monthly | H37: No | I37: - | J37: Yes | K37: 20 | L37: 10 | M37: 20
A38: 3262 | B38: Tânia Barros | C38: Core | D38: 45379 | E38: Yes | F38: 5 | G38: Annual | H38: No | I38: - | J38: No | K38: 0 | L38: 0 | M38: 5
A39: 3263 | B39: Vinicius Lima | C39: Ultimate | D39: 45380 | E39: No | F39: 15 | G39: Monthly | H39: Yes | I39: 30 | J39: Yes | K39: 20 | L39: 3 | M39: 62
A40: 3264 | B40: Yasmin Teixeira | C40: Standard | D40: 45381 | E40: Yes | F40: 10 | G40: Quarterly | H40: No | I40: - | J40: Yes | K40: 20 | L40: 15 | M40: 15
A41: 3265 | B41: Zé Carlos | C41: Core | D41: 45382 | E41: No | F41: 5 | G41: Monthly | H41: No | I41: - | J41: No | K41: 0 | L41: 1 | M41: 4
...
